Workbook

Sheet Applicants_Raw
A1: Student_ID | B1: Name | C1: Department | D1: Student_Department | E1: Application_Date | F1: Standarad_Date | G1: Test_1_Score | H1: Test_2_Score | I1: Test_3_Score | J1: Weighted_Score | K1: Attendance_% | L1: Assignment_Completion_% | M1: Standard_Assignment_Completion_% | N1: Internship_Pref | O1: Required_Score | P1: Required_Attendance | Q1: Eligibility | R1: Allocation_Status
A2: S324 | B2: Imran Khan | C2: Electro | D2: =vlookup(C2,Dept_Lookup!A$1:B$17,2,false) -> Electronics | E2: 45866 | F2: =IFERROR(DATEVALUE(E2),DATE(RIGHT(E2,2)+2000,MID(E2,4,2),LEFT(E2,2))) -> 45866 | G2: 86 | H2: 96 | I2: 92 | J2: =G2*Scoring_Weights!B$2+H2*Scoring_Weights!B$3+I2*Scoring_Weights!B$4 -> 92.5 | K2: 0.95 | L2: 0.97 | M2: =if(L2>1,L2/100,L2) -> 0.97 | N2: Company A | O2: =vlookup(N2,Interview_Slots!$A$1:$D$5,3,false) -> 65 | P2: =vlookup(N2,Interview_Slots!$A$1:$D$5,4,false) -> 75 | Q2: =IF(AND(J2>=O2,K2>=P2/100),"Eligible","Not Eligible") -> Eligible | R2: yes
A3: S053 | B3: Sunita Singh | C3: Computer Science | D3: =vlookup(C3,Dept_Lookup!A$1:B$17,2,false) -> Computer Science | E3: 45866 | F3: =IFERROR(DATEVALUE(E3),DATE(RIGHT(E3,2)+2000,MID(E3,4,2),LEFT(E3,2))) -> 45866 | G3: 97 | H3: 81 | I3: 98 | J3: =G3*Scoring_Weights!B$2+H3*Scoring_Weights!B$3+I3*Scoring_Weights!B$4 -> 91.9 | K3: 0.86 | L3: 0.85 | M3: =if(L3>1,L3/100,L3) -> 0.85 | N3: Company A | O3: =vlookup(N3,Interview_Slots!$A$1:$D$5,3,false) -> 65 | P3: =vlookup(N3,Interview_Slots!$A$1:$D$5,4,false) -> 75 | Q3: =IF(AND(J3>=O3,K3>=P3/100),"Eligible","Not Eligible") -> Eligible | R3: yes
A4: S005 | B4: Anika Mukherjee | C4: ECE | D4: =vlookup(C4,Dept_Lookup!A$1:B$17,2,false) -> Electronics | E4: 45915 | F4: =IFERROR(DATEVALUE(E4),DATE(RIGHT(E4,2)+2000,MID(E4,4,2),LEFT(E4,2))) -> 45915 | G4: 78 | H4: 91 | I4: 96 | J4: =G4*Scoring_Weights!B$2+H4*Scoring_Weights!B$3+I4*Scoring_Weights!B$4 -> 91.55 | K4: 0.81 | L4: 0.73 | M4: =if(L4>1,L4/100,L4) -> 0.73 | N4: Company A | O4: =vlookup(N4,Interview_Slots!$A$1:$D$5,3,false) -> 65 | P4: =vlookup(N4,Interview_Slots!$A$1:$D$5,4,false) -> 75 | Q4: =IF(AND(J4>=O4,K4>=P4/100),"Eligible","Not Eligible") -> Eligible | R4: yes
A5: S110 | B5: Priti Sharma | C5: ECE | D5: =vlookup(C5,Dept_Lookup!A$1:B$17,2,false) -> Electronics | E5: 45882 | F5: =IFERROR(DATEVALUE(E5),DATE(RIGHT(E5,2)+2000,MID(E5,4,2),LEFT(E5,2))) -> 45882 | G5: 80 | H5: 87 | I5: 98 | J5: =G5*Scoring_Weights!B$2+H5*Scoring_Weights!B$3+I5*Scoring_Weights!B$4 -> 91.45 | K5: 0.94 | L5: 0.93 | M5: =if(L5>1,L5/100,L5) -> 0.93 | N5: Company A | O5: =vlookup(N5,Interview_Slots!$A$1:$D$5,3,false) -> 65 | P5: =vlookup(N5,Interview_Slots!$A$1:$D$5,4,false) -> 75 | Q5: =IF(AND(J5>=O5,K5>=P5/100),"Eligible","Not Eligible") -> Eligible | R5: yes
A6: S233 | B6: Nisha Kapoor | C6: Computer Science | D6: =vlookup(C6,Dept_Lookup!A$1:B$17,2,false) -> Computer Science | E6: 45893 | F6: =IFERROR(DATEVALUE(E6),DATE(RIGHT(E6,2)+2000,MID(E6,4,2),LEFT(E6,2))) -> 45893 | G6: 80 | H6: 87 | I6: 98 | J6: =G6*Scoring_Weights!B$2+H6*Scoring_Weights!B$3+I6*Scoring_Weights!B$4 -> 91.45 | K6: 0.78 | L6: 0.96 | M6: =if(L6>1,L6/100,L6) -> 0.96 | N6: Company A | O6: =vlookup(N6,Interview_Slots!$A$1:$D$5,3,false) -> 65 | P6: =vlookup(N6,Interview_Slots!$A$1:$D$5,4,false) -> 75 | Q6: =IF(AND(J6>=O6,K6>=P6/100),"Eligible","Not Eligible") -> Eligible | R6: yes
A7: S307 | B7: Tushar Kapoor | C7: Electronics | D7: =vlookup(C7,Dept_Lookup!A$1:B$17,2,false) -> Electronics | E7: 45865 | F7: =IFERROR(DATEVALUE(E7),DATE(RIGHT(E7,2)+2000,MID(E7,4,2),LEFT(E7,2))) -> 45865 | G7: 68 | H7: 90 | I7: 98 | J7: =G7*Scoring_Weights!B$2+H7*Scoring_Weights!B$3+I7*Scoring_Weights!B$4 -> 90.7 | K7: 0.84 | L7: 0.9 | M7: =if(L7>1,L7/100,L7) -> 0.9 | N7: Company A | O7: =vlookup(N7,Interview_Slots!$A$1:$D$5,3,false) -> 65 | P7: =vlookup(N7,Interview_Slots!$A$1:$D$5,4,false) -> 75 | Q7: =IF(AND(J7>=O7,K7>=P7/100),"Eligible","Not Eligible") -> Eligible | R7: yes
A8: S323 | B8: Priyanka Verma | C8: Mechanical Engg | D8: =vlookup(C8,Dept_Lookup!A$1:B$17,2,false) -> Mechanical | E8: 45921 | F8: =IFERROR(DATEVALUE(E8),DATE(RIGHT(E8,2)+2000,MID(E8,4,2),LEFT(E8,2))) -> 45921 | G8: 92 | H8: 81 | I8: 97 | J8: =G8*Scoring_Weights!B$2+H8*Scoring_Weights!B$3+I8*Scoring_Weights!B$4 -> 90.65 | K8: 0.84 | L8: 0.82 | M8: =if(L8>1,L8/100,L8) -> 0.82 | N8: Company A | O8: =vlookup(N8,Interview_Slots!$A$1:$D$5,3,false) -> 65 | P8: =vlookup(N8,Interview_Slots!$A$1:$D$5,4,false) -> 75 | Q8: =IF(AND(J8>=O8,K8>=P8/100),"Eligible","Not Eligible") -> Eligible | R8: yes
A9: S045 | B9: Ritu Mehta | C9: Mech | D9: =vlookup(C9,Dept_Lookup!A$1:B$17,2,false) -> Mechanical | E9: 45915 | F9: =IFERROR(DATEVALUE(E9),DATE(RIGHT(E9,2)+2000,MID(E9,4,2),LEFT(E9,2))) -> 45915 | G9: 77 | H9: 93 | I9: 92 | J9: =G9*Scoring_Weights!B$2+H9*Scoring_Weights!B$3+I9*Scoring_Weights!B$4 -> 90.1 | K9: 0.87 | L9: 0.8 | M9: =if(L9>1,L9/100,L9) -> 0.8 | N9: Company A | O9: =vlookup(N9,Interview_Slots!$A$1:$D$5,3,false) -> 65 | P9: =vlookup(N9,Interview_Slots!$A$1:$D$5,4,false) -> 75 | Q9: =IF(AND(J9>=O9,K9>=P9/100),"Eligible","Not Eligible") -> Eligible | R9: yes
A10: S427 | B10: Farah Khan | C10: CSE | D10: =vlookup(C10,Dept_Lookup!A$1:B$17,2,false) -> Computer Science | E10: 45900 | F10: =IFERROR(DATEVALUE(E10),DATE(RIGHT(E10,2)+2000,MID(E10,4,2),LEFT(E10,2))) -> 45900 | G10: 88 | H10: 92 | I10: 88 | J10: =G10*Scoring_Weights!B$2+H10*Scoring_Weights!B$3+I10*Scoring_Weights!B$4 -> 89.4 | K10: 0.9 | L10: 0.97 | M10: =if(L10>1,L10/100,L10) -> 0.97 | N10: Company A | O10: =vlookup(N10,Interview_Slots!$A$1:$D$5,3,false) -> 65 | P10: =vlookup(N10,Interview_Slots!$A$1:$D$5,4,false) -> 75 | Q10: =IF(AND(J10>=O10,K10>=P10/100),"Eligible","Not Eligible") -> Eligible | R10: yes
A11: S056 | B11: Bhavna Das | C11: CIV | D11: =vlookup(C11,Dept_Lookup!A$1:B$17,2,false) -> Civil | E11: 45855 | F11: =IFERROR(DATEVALUE(E11),DATE(RIGHT(E11,2)+2000,MID(E11,4,2),LEFT(E11,2))) -> 45855 | G11: 82 | H11: 80 | I11: 97 | J11: =G11*Scoring_Weights!B$2+H11*Scoring_Weights!B$3+I11*Scoring_Weights!B$4 -> 88.8 | K11: 0.87 | L11: 0.73 | M11: =if(L11>1,L11/100,L11) -> 0.73 | N11: Company A | O11: =vlookup(N11,Interview_Slots!$A$1:$D$5,3,false) -> 65 | P11: =vlookup(N11,Interview_Slots!$A$1:$D$5,4,false) -> 75 | Q11: =IF(AND(J11>=O11,K11>=P11/100),"Eligible","Not Eligible") -> Eligible | R11: yes
A12: S243 | B12: Ishwari Rao | C12: ELEC | D12: =vlookup(C12,Dept_Lookup!A$1:B$17,2,false) -> Electronics | E12: 45878 | F12: =IFERROR(DATEVALUE(E12),DATE(RIGHT(E12,2)+2000,MID(E12,4,2),LEFT(E12,2))) -> 45878 | G12: 82 | H12: 95 | I12: 86 | J12: =G12*Scoring_Weights!B$2+H12*Scoring_Weights!B$3+I12*Scoring_Weights!B$4 -> 88.55 | K12: 0.79 | L12: 0.83 | M12: =if(L12>1,L12/100,L12) -> 0.83 | N12: Company A | O12: =vlookup(N12,Interview_Slots!$A$1:$D$5,3,false) -> 65 | P12: =vlookup(N12,Interview_Slots!$A$1:$D$5,4,false) -> 75 | Q12: =IF(AND(J12>=O12,K12>=P12/100),"Eligible","Not Eligible") -> Eligible | R12: yes
A13: S300 | B13: Sandeep Nair | C13: ECE | D13: =vlookup(C13,Dept_Lookup!A$1:B$17,2,false) -> Electronics | E13: 45929 | F13: =IFERROR(DATEVALUE(E13),DATE(RIGHT(E13,2)+2000,MID(E13,4,2),LEFT(E13,2))) -> 45929 | G13: 61 | H13: 95 | I13: 91 | J13: =G13*Scoring_Weights!B$2+H13*Scoring_Weights!B$3+I13*Scoring_Weights!B$4 -> 87.9 | K13: 0.85 | L13: 1 | M13: =if(L13>1,L13/100,L13) -> 1 | N13: Company A | O13: =vlookup(N13,Interview_Slots!$A$1:$D$5,3,false) -> 65 | P13: =vlookup(N13,Interview_Slots!$A$1:$D$5,4,false) -> 75 | Q13: =IF(AND(J13>=O13,K13>=P13/100),"Eligible","Not Eligible") -> Eligible | R13: yes
... A15: S067 | B15: Arvind Sharma | C15: CS | D15: =vlookup(C15,Dept_Lookup!A$1:B$17,2,false) -> Computer Science | E15: 45887 | F15: =IFERROR(DATEVALUE(E15),DATE(RIGHT(E15,2)+2000,MID(E15,4,2),LEFT(E15,2))) -> 45887 | G15: 72 | H15: 88 | I15: 92 | J15: =G15*Scoring_Weights!B$2+H15*Scoring_Weights!B$3+I15*Scoring_Weights!B$4 -> 87.6 | K15: 0.9 | L15: 0.84 | M15: =if(L15>1,L15/100,L15) -> 0.84 | N15: Company A | O15: =vlookup(N15,Interview_Slots!$A$1:$D$5,3,false) -> 65 | P15: =vlookup(N15,Interview_Slots!$A$1:$D$5,4,false) -> 75 | Q15: =IF(AND(J15>=O15,K15>=P15/100),"Eligible","Not Eligible") -> Eligible | R15: yes
A16: S024 | B16: Vihaan Singh | C16: Mech | D16: =vlookup(C16,Dept_Lookup!A$1:B$17,2,false) -> Mechanical | E16: 45872 | F16: =IFERROR(DATEVALUE(E16),DATE(RIGHT(E16,2)+2000,MID(E16,4,2),LEFT(E16,2))) -> 45872 | G16: 87 | H16: 77 | I16: 95 | J16: =G16*Scoring_Weights!B$2+H16*Scoring_Weights!B$3+I16*Scoring_Weights!B$4 -> 87.5 | K16: 0.72 | L16: 0.99 | M16: =if(L16>1,L16/100,L16) -> 0.99 | N16: Company A | O16: =vlookup(N16,Interview_Slots!$A$1:$D$5,3,false) -> 65 | P16: =vlookup(N16,Interview_Slots!$A$1:$D$5,4,false) -> 75 | Q16: =IF(AND(J16>=O16,K16>=P16/100),"Eligible","Not Eligible") -> Not Eligible
A17: S343 | B17: Niranjan Gupta | C17: Electronics | D17: =vlookup(C17,Dept_Lookup!A$1:B$17,2,false) -> Electronics | E17: 45902 | F17: =IFERROR(DATEVALUE(E17),DATE(RIGHT(E17,2)+2000,MID(E17,4,2),LEFT(E17,2))) -> 45902 | G17: 94 | H17: 92 | I17: 82 | J17: =G17*Scoring_Weights!B$2+H17*Scoring_Weights!B$3+I17*Scoring_Weights!B$4 -> 87.3 | K17: 0.76 | L17: 0.8 | M17: =if(L17>1,L17/100,L17) -> 0.8 | N17: Company A | O17: =vlookup(N17,Interview_Slots!$A$1:$D$5,3,false) -> 65 | P17: =vlookup(N17,Interview_Slots!$A$1:$D$5,4,false) -> 75 | Q17: =IF(AND(J17>=O17,K17>=P17/100),"Eligible","Not Eligible") -> Eligible | R17: yes
A18: S036 | B18: Aisha Khan | C18: Computer Science | D18: =vlookup(C18,Dept_Lookup!A$1:B$17,2,false) -> Computer Science | E18: 45900 | F18: =IFERROR(DATEVALUE(E18),DATE(RIGHT(E18,2)+2000,MID(E18,4,2),LEFT(E18,2))) -> 45900 | G18: 64 | H18: 86 | I18: 95 | J18: =G18*Scoring_Weights!B$2+H18*Scoring_Weights!B$3+I18*Scoring_Weights!B$4 -> 87.2 | K18: 0.76 | L18: 0.8 | M18: =if(L18>1,L18/100,L18) -> 0.8 | N18: Company A | O18: =vlookup(N18,Interview_Slots!$A$1:$D$5,3,false) -> 65 | P18: =vlookup(N18,Interview_Slots!$A$1:$D$5,4,false) -> 75 | Q18: =IF(AND(J18>=O18,K18>=P18/100),"Eligible","Not Eligible") -> Eligible | R18: yes
A19: S288 | B19: Pooja Singh | C19: Mechanical Engg | D19: =vlookup(C19,Dept_Lookup!A$1:B$17,2,false) -> Mechanical | E19: 45860 | F19: =IFERROR(DATEVALUE(E19),DATE(RIGHT(E19,2)+2000,MID(E19,4,2),LEFT(E19,2))) -> 45860 | G19: 93 | H19: 77 | I19: 92 | J19: =G19*Scoring_Weights!B$2+H19*Scoring_Weights!B$3+I19*Scoring_Weights!B$4 -> 86.9 | K19: 0.84 | L19: 0.76 | M19: =if(L19>1,L19/100,L19) -> 0.76 | N19: Company A | O19: =vlookup(N19,Interview_Slots!$A$1:$D$5,3,false) -> 65 | P19: =vlookup(N19,Interview_Slots!$A$1:$D$5,4,false) -> 75 | Q19: =IF(AND(J19>=O19,K19>=P19/100),"Eligible","Not Eligible") -> Eligible | R19: yes
A20: S022 | B20: Devendra Patel | C20: Electro | D20: =vlookup(C20,Dept_Lookup!A$1:B$17,2,false) -> Electronics | E20: 45900 | F20: =IFERROR(DATEVALUE(E20),DATE(RIGHT(E20,2)+2000,MID(E20,4,2),LEFT(E20,2))) -> 45900 | G20: 73 | H20: 95 | I20: 85 | J20: =G20*Scoring_Weights!B$2+H20*Scoring_Weights!B$3+I20*Scoring_Weights!B$4 -> 86.7 | K20: 0.89 | L20: 0.93 | M20: =if(L20>1,L20/100,L20) -> 0.93 | N20: Company A | O20: =vlookup(N20,Interview_Slots!$A$1:$D$5,3,false) -> 65 | P20: =vlookup(N20,Interview_Slots!$A$1:$D$5,4,false) -> 75 | Q20: =IF(AND(J20>=O20,K20>=P20/100),"Eligible","Not Eligible") -> Eligible | R20: yes
A21: S416 | B21: Nitin Bhatia | C21: CSE | D21: =vlookup(C21,Dept_Lookup!A$1:B$17,2,false) -> Computer Science | E21: 45854 | F21: =IFERROR(DATEVALUE(E21),DATE(RIGHT(E21,2)+2000,MID(E21,4,2),LEFT(E21,2))) -> 45854 | G21: 69 | H21: 81 | I21: 96 | J21: =G21*Scoring_Weights!B$2+H21*Scoring_Weights!B$3+I21*Scoring_Weights!B$4 -> 86.7 | K21: 0.8 | L21: 0.82 | M21: =if(L21>1,L21/100,L21) -> 0.82 | N21: Company A | O21: =vlookup(N21,Interview_Slots!$A$1:$D$5,3,false) -> 65 | P21: =vlookup(N21,Interview_Slots!$A$1:$D$5,4,false) -> 75 | Q21: =IF(AND(J21>=O21,K21>=P21/100),"Eligible","Not Eligible") -> Eligible | R21: yes
A22: S411 | B22: Lokesh Reddy | C22: ME | D22: =vlookup(C22,Dept_Lookup!A$1:B$17,2,false) -> Mechanical | E22: 45889 | F22: =IFERROR(DATEVALUE(E22),DATE(RIGHT(E22,2)+2000,MID(E22,4,2),LEFT(E22,2))) -> 45889 | G22: 97 | H22: 80 | I22: 88 | J22: =G22*Scoring_Weights!B$2+H22*Scoring_Weights!B$3+I22*Scoring_Weights!B$4 -> 86.55 | K22: 0.84 | L22: 0.77 | M22: =if(L22>1,L22/100,L22) -> 0.77 | N22: Company A | O22: =vlookup(N22,Interview_Slots!$A$1:$D$5,3,false) -> 65 | P22: =vlookup(N22,Interview_Slots!$A$1:$D$5,4,false) -> 75 | Q22: =IF(AND(J22>=O22,K22>=P22/100),"Eligible","Not Eligible") -> Eligible | R22: yes
A23: S318 | B23: Yuvraj Choudhury | C23: CS | D23: =vlookup(C23,Dept_Lookup!A$1:B$17,2,false) -> Computer Science | E23: 45842 | F23: =IFERROR(DATEVALUE(E23),DATE(RIGHT(E23,2)+2000,MID(E23,4,2),LEFT(E23,2))) -> 45842 | G23: 73 | H23: 97 | I23: 83 | J23: =G23*Scoring_Weights!B$2+H23*Scoring_Weights!B$3+I23*Scoring_Weights!B$4 -> 86.4 | K23: 0.8 | L23: 0.89 | M23: =if(L23>1,L23/100,L23) -> 0.89 | N23: Company A | O23: =vlookup(N23,Interview_Slots!$A$1:$D$5,3,false) -> 65 | P23: =vlookup(N23,Interview_Slots!$A$1:$D$5,4,false) -> 75 | Q23: =IF(AND(J23>=O23,K23>=P23/100),"Eligible","Not Eligible") -> Eligible | R23: yes
A24: S172 | B24: Nilesh Mehta | C24: Mechanical Engg | D24: =vlookup(C24,Dept_Lookup!A$1:B$17,2,false) -> Mechanical | E24: 45875 | F24: =IFERROR(DATEVALUE(E24),DATE(RIGHT(E24,2)+2000,MID(E24,4,2),LEFT(E24,2))) -> 45875 | G24: 98 | H24: 83 | I24: 85 | J24: =G24*Scoring_Weights!B$2+H24*Scoring_Weights!B$3+I24*Scoring_Weights!B$4 -> 86.25 | K24: 0.89 | L24: 0.78 | M24: =if(L24>1,L24/100,L24) -> 0.78 | N24: Company A | O24: =vlookup(N24,Interview_Slots!$A$1:$D$5,3,false) -> 65 | P24: =vlookup(N24,Interview_Slots!$A$1:$D$5,4,false) -> 75 | Q24: =IF(AND(J24>=O24,K24>=P24/100),"Eligible","Not Eligible") -> Eligible | R24: yes
A25: S152 | B25: Seema Gupta | C25: Mechanical Engg | D25: =vlookup(C25,Dept_Lookup!A$1:B$17,2,false) -> Mechanical | E25: 45867 | F25: =IFERROR(DATEVALUE(E25),DATE(RIGHT(E25,2)+2000,MID(E25,4,2),LEFT(E25,2))) -> 45867 | G25: 95 | H25: 79 | I25: 88 | J25: =G25*Scoring_Weights!B$2+H25*Scoring_Weights!B$3+I25*Scoring_Weights!B$4 -> 85.9 | K25: 0.86 | L25: 0.82 | M25: =if(L25>1,L25/100,L25) -> 0.82 | N25: Company A | O25: =vlookup(N25,Interview_Slots!$A$1:$D$5,3,false) -> 65 | P25: =vlookup(N25,Interview_Slots!$A$1:$D$5,4,false) -> 75 | Q25: =IF(AND(J25>=O25,K25>=P25/100),"Eligible","Not Eligible") -> Eligible | R25: yes
A26: S059 | B26: Rameshwar Das | C26: Computer Science | D26: =vlookup(C26,Dept_Lookup!A$1:B$17,2,false) -> Computer Science | E26: 45913 | F26: =IFERROR(DATEVALUE(E26),DATE(RIGHT(E26,2)+2000,MID(E26,4,2),LEFT(E26,2))) -> 45913 | G26: 63 | H26: 85 | I26: 93 | J26: =G26*Scoring_Weights!B$2+H26*Scoring_Weights!B$3+I26*Scoring_Weights!B$4 -> 85.7 | K26: 0.82 | L26: 0.81 | M26: =if(L26>1,L26/100,L26) -> 0.81 | N26: Company A | O26: =vlookup(N26,Interview_Slots!$A$1:$D$5,3,false) -> 65 | P26: =vlookup(N26,Interview_Slots!$A$1:$D$5,4,false) -> 75 | Q26: =IF(AND(J26>=O26,K26>=P26/100),"Eligible","Not Eligible") -> Eligible | R26: yes
A27: S125 | B27: Lalit Verma | C27: Civil Engg | D27: =vlookup(C27,Dept_Lookup!A$1:B$17,2,false) -> Civil | E27: 45866 | F27: =IFERROR(DATEVALUE(E27),DATE(RIGHT(E27,2)+2000,MID(E27,4,2),LEFT(E27,2))) -> 45866 | G27: 98 | H27: 66 | I27: 95 | J27: =G27*Scoring_Weights!B$2+H27*Scoring_Weights!B$3+I27*Scoring_Weights!B$4 -> 85.3 | K27: 0.91 | L27: 1 | M27: =if(L27>1,L27/100,L27) -> 1 | N27: Company A | O27: =vlookup(N27,Interview_Slots!$A$1:$D$5,3,false) -> 65 | P27: =vlookup(N27,Interview_Slots!$A$1:$D$5,4,false) -> 75 | Q27: =IF(AND(J27>=O27,K27>=P27/100),"Eligible","Not Eligible") -> Eligible | R27: yes
A28: S137 | B28: Vaidehi Nair | C28: Computer Science | D28: =vlookup(C28,Dept_Lookup!A$1:B$17,2,false) -> Computer Science | E28: 45871 | F28: =IFERROR(DATEVALUE(E28),DATE(RIGHT(E28,2)+2000,MID(E28,4,2),LEFT(E28,2))) -> 45871 | G28: 98 | H28: 66 | I28: 95 | J28: =G28*Scoring_Weights!B$2+H28*Scoring_Weights!B$3+I28*Scoring_Weights!B$4 -> 85.3 | K28: 0.91 | L28: 1 | M28: =if(L28>1,L28/100,L28) -> 1 | N28: Company A | O28: =vlookup(N28,Interview_Slots!$A$1:$D$5,3,false) -> 65 | P28: =vlookup(N28,Interview_Slots!$A$1:$D$5,4,false) -> 75 | Q28: =IF(AND(J28>=O28,K28>=P28/100),"Eligible","Not Eligible") -> Eligible | R28: yes
... A30: S227 | B30: Asha Malhotra | C30: Electro | D30: =vlookup(C30,Dept_Lookup!A$1:B$17,2,false) -> Electronics | E30: 45893 | F30: =IFERROR(DATEVALUE(E30),DATE(RIGHT(E30,2)+2000,MID(E30,4,2),LEFT(E30,2))) -> 45893 | G30: 66 | H30: 78 | I30: 95 | J30: =G30*Scoring_Weights!B$2+H30*Scoring_Weights!B$3+I30*Scoring_Weights!B$4 -> 84.7 | K30: 0.87 | L30: 0.94 | M30: =if(L30>1,L30/100,L30) -> 0.94 | N30: Company A | O30: =vlookup(N30,Interview_Slots!$A$1:$D$5,3,false) -> 65 | P30: =vlookup(N30,Interview_Slots!$A$1:$D$5,4,false) -> 75 | Q30: =IF(AND(J30>=O30,K30>=P30/100),"Eligible","Not Eligible") -> Eligible | R30: yes
A31: S120 | B31: Ajith Iyer | C31: CIV | D31: =vlookup(C31,Dept_Lookup!A$1:B$17,2,false) -> Civil | E31: 29/08/25 | F31: =IFERROR(DATEVALUE(E31),DATE(RIGHT(E31,2)+2000,MID(E31,4,2),LEFT(E31,2))) -> 45898 | G31: 70 | H31: 94 | I31: 82 | J31: =G31*Scoring_Weights!B$2+H31*Scoring_Weights!B$3+I31*Scoring_Weights!B$4 -> 84.4 | K31: 0.83 | L31: 0.86 | M31: =if(L31>1,L31/100,L31) -> 0.86 | N31: Company A | O31: =vlookup(N31,Interview_Slots!$A$1:$D$5,3,false) -> 65 | P31: =vlookup(N31,Interview_Slots!$A$1:$D$5,4,false) -> 75 | Q31: =IF(AND(J31>=O31,K31>=P31/100),"Eligible","Not Eligible") -> Eligible | R31: yes
A32: S105 | B32: Monika Gupta | C32: ME | D32: =vlookup(C32,Dept_Lookup!A$1:B$17,2,false) -> Mechanical | E32: 45870 | F32: =IFERROR(DATEVALUE(E32),DATE(RIGHT(E32,2)+2000,MID(E32,4,2),LEFT(E32,2))) -> 45870 | G32: 76 | H32: 97 | I32: 78 | J32: =G32*Scoring_Weights!B$2+H32*Scoring_Weights!B$3+I32*Scoring_Weights!B$4 -> 84.35 | K32: 0.83 | L32: 0.91 | M32: =if(L32>1,L32/100,L32) -> 0.91 | N32: Company A | O32: =vlookup(N32,Interview_Slots!$A$1:$D$5,3,false) -> 65 | P32: =vlookup(N32,Interview_Slots!$A$1:$D$5,4,false) -> 75 | Q32: =IF(AND(J32>=O32,K32>=P32/100),"Eligible","Not Eligible") -> Eligible | R32: yes
A33: S133 | B33: Varun Shetty | C33: Electro | D33: =vlookup(C33,Dept_Lookup!A$1:B$17,2,false) -> Electronics | E33: 45900 | F33: =IFERROR(DATEVALUE(E33),DATE(RIGHT(E33,2)+2000,MID(E33,4,2),LEFT(E33,2))) -> 45900 | G33: 85 | H33: 80 | I33: 87 | J33: =G33*Scoring_Weights!B$2+H33*Scoring_Weights!B$3+I33*Scoring_Weights!B$4 -> 84.25 | K33: 0.83 | L33: 0.96 | M33: =if(L33>1,L33/100,L33) -> 0.96 | N33: Company A | O33: =vlookup(N33,Interview_Slots!$A$1:$D$5,3,false) -> 65 | P33: =vlookup(N33,Interview_Slots!$A$1:$D$5,4,false) -> 75 | Q33: =IF(AND(J33>=O33,K33>=P33/100),"Eligible","Not Eligible") -> Eligible | R33: yes
A34: S009 | B34: Vihaan Singh | C34: Mech | D34: =vlookup(C34,Dept_Lookup!A$1:B$17,2,false) -> Mechanical | E34: 45874 | F34: =IFERROR(DATEVALUE(E34),DATE(RIGHT(E34,2)+2000,MID(E34,4,2),LEFT(E34,2))) -> 45874 | G34: 77 | H34: 90 | I34: 82 | J34: =G34*Scoring_Weights!B$2+H34*Scoring_Weights!B$3+I34*Scoring_Weights!B$4 -> 84.05 | K34: 0.79 | L34: 0.84 | M34: =if(L34>1,L34/100,L34) -> 0.84 | N34: Company A | O34: =vlookup(N34,Interview_Slots!$A$1:$D$5,3,false) -> 65 | P34: =vlookup(N34,Interview_Slots!$A$1:$D$5,4,false) -> 75 | Q34: =IF(AND(J34>=O34,K34>=P34/100),"Eligible","Not Eligible") -> Eligible | R34: yes
A35: S375 | B35: Kavitha Nair | C35: Electronics | D35: =vlookup(C35,Dept_Lookup!A$1:B$17,2,false) -> Electronics | E35: 45900 | F35: =IFERROR(DATEVALUE(E35),DATE(RIGHT(E35,2)+2000,MID(E35,4,2),LEFT(E35,2))) -> 45900 | G35: 62 | H35: 79 | I35: 94 | J35: =G35*Scoring_Weights!B$2+H35*Scoring_Weights!B$3+I35*Scoring_Weights!B$4 -> 83.95 | K35: 0.81 | L35: 0.79 | M35: =if(L35>1,L35/100,L35) -> 0.79 | N35: Company A | O35: =vlookup(N35,Interview_Slots!$A$1:$D$5,3,false) -> 65 | P35: =vlookup(N35,Interview_Slots!$A$1:$D$5,4,false) -> 75 | Q35: =IF(AND(J35>=O35,K35>=P35/100),"Eligible","Not Eligible") -> Eligible | R35: yes
A36: S066 | B36: Tejas Malhotra | C36: Comp Sci | D36: =vlookup(C36,Dept_Lookup!A$1:B$17,2,false) -> Computer Science | E36: 45882 | F36: =IFERROR(DATEVALUE(E36),DATE(RIGHT(E36,2)+2000,MID(E36,4,2),LEFT(E36,2))) -> 45882 | G36: 90 | H36: 69 | I36: 92 | J36: =G36*Scoring_Weights!B$2+H36*Scoring_Weights!B$3+I36*Scoring_Weights!B$4 -> 83.65 | K36: 0.87 | L36: 0.96 | M36: =if(L36>1,L36/100,L36) -> 0.96 | N36: Company A | O36: =vlookup(N36,Interview_Slots!$A$1:$D$5,3,false) -> 65 | P36: =vlookup(N36,Interview_Slots!$A$1:$D$5,4,false) -> 75 | Q36: =IF(AND(J36>=O36,K36>=P36/100),"Eligible","Not Eligible") -> Eligible | R36: yes
A37: S079 | B37: Deepak Verma | C37: CE | D37: =vlookup(C37,Dept_Lookup!A$1:B$17,2,false) -> Civil | E37: 45900 | F37: =IFERROR(DATEVALUE(E37),DATE(RIGHT(E37,2)+2000,MID(E37,4,2),LEFT(E37,2))) -> 45900 | G37: 94 | H37: 84 | I37: 80 | J37: =G37*Scoring_Weights!B$2+H37*Scoring_Weights!B$3+I37*Scoring_Weights!B$4 -> 83.5 | K37: 0.95 | L37: 0.76 | M37: =if(L37>1,L37/100,L37) -> 0.76 | N37: Company A | O37: =vlookup(N37,Interview_Slots!$A$1:$D$5,3,false) -> 65 | P37: =vlookup(N37,Interview_Slots!$A$1:$D$5,4,false) -> 75 | Q37: =IF(AND(J37>=O37,K37>=P37/100),"Eligible","Not Eligible") -> Eligible | R37: yes
A38: S333 | B38: Kiran Joshi | C38: Civil | D38: =vlookup(C38,Dept_Lookup!A$1:B$17,2,false) -> Civil | E38: 45854 | F38: =IFERROR(DATEVALUE(E38),DATE(RIGHT(E38,2)+2000,MID(E38,4,2),LEFT(E38,2))) -> 45854 | G38: 83 | H38: 73 | I38: 91 | J38: =G38*Scoring_Weights!B$2+H38*Scoring_Weights!B$3+I38*Scoring_Weights!B$4 -> 83.5 | K38: 0.87 | L38: 0.97 | M38: =if(L38>1,L38/100,L38) -> 0.97 | N38: Company A | O38: =vlookup(N38,Interview_Slots!$A$1:$D$5,3,false) -> 65 | P38: =vlookup(N38,Interview_Slots!$A$1:$D$5,4,false) -> 75 | Q38: =IF(AND(J38>=O38,K38>=P38/100),"Eligible","Not Eligible") -> Eligible | R38: yes
A39: S026 | B39: Pranav Kulkarni | C39: Mech | D39: =vlookup(C39,Dept_Lookup!A$1:B$17,2,false) -> Mechanical | E39: 45895 | F39: =IFERROR(DATEVALUE(E39),DATE(RIGHT(E39,2)+2000,MID(E39,4,2),LEFT(E39,2))) -> 45895 | G39: 92 | H39: 92 | I39: 75 | J39: =G39*Scoring_Weights!B$2+H39*Scoring_Weights!B$3+I39*Scoring_Weights!B$4 -> 83.5 | K39: 0.82 | L39: 0.81 | M39: =if(L39>1,L39/100,L39) -> 0.81 | N39: Company A | O39: =vlookup(N39,Interview_Slots!$A$1:$D$5,3,false) -> 65 | P39: =vlookup(N39,Interview_Slots!$A$1:$D$5,4,false) -> 75 | Q39: =IF(AND(J39>=O39,K39>=P39/100),"Eligible","Not Eligible") -> Eligible | R39: yes
A40: S040 | B40: Kavya Iyer | C40: Electronics | D40: =vlookup(C40,Dept_Lookup!A$1:B$17,2,false) -> Electronics | E40: 45869 | F40: =IFERROR(DATEVALUE(E40),DATE(RIGHT(E40,2)+2000,MID(E40,4,2),LEFT(E40,2))) -> 45869 | G40: 97 | H40: 70 | I40: 88 | J40: =G40*Scoring_Weights!B$2+H40*Scoring_Weights!B$3+I40*Scoring_Weights!B$4 -> 83.05 | K40: 0.92 | L40: 0.89 | M40: =if(L40>1,L40/100,L40) -> 0.89 | N40: Company A | O40: =vlookup(N40,Interview_Slots!$A$1:$D$5,3,false) -> 65 | P40: =vlookup(N40,Interview_Slots!$A$1:$D$5,4,false) -> 75 | Q40: =IF(AND(J40>=O40,K40>=P40/100),"Eligible","Not Eligible") -> Eligible | R40: yes
A41: S221 | B41: Abhay Gupta | C41: Electro | D41: =vlookup(C41,Dept_Lookup!A$1:B$17,2,false) -> Electronics | E41: 45865 | F41: =IFERROR(DATEVALUE(E41),DATE(RIGHT(E41,2)+2000,MID(E41,4,2),LEFT(E41,2))) -> 45865 | G41: 97 | H41: 70 | I41: 88 | J41: =G41*Scoring_Weights!B$2+H41*Scoring_Weights!B$3+I41*Scoring_Weights!B$4 -> 83.05 | K41: 0.92 | L41: 0.89 | M41: =if(L41>1,L41/100,L41) -> 0.89 | N41: Company A | O41: =vlookup(N41,Interview_Slots!$A$1:$D$5,3,false) -> 65 | P41: =vlookup(N41,Interview_Slots!$A$1:$D$5,4,false) -> 75 | Q41: =IF(AND(J41>=O41,K41>=P41/100),"Eligible","Not Eligible") -> Eligible | R41: yes
A42: S382 | B42: Harini Reddy | C42: Mechanical Engg | D42: =vlookup(C42,Dept_Lookup!A$1:B$17,2,false) -> Mechanical | E42: 45900 | F42: =IFERROR(DATEVALUE(E42),DATE(RIGHT(E42,2)+2000,MID(E42,4,2),LEFT(E42,2))) -> 45900 | G42: 77 | H42: 84 | I42: 84 | J42: =G42*Scoring_Weights!B$2+H42*Scoring_Weights!B$3+I42*Scoring_Weights!B$4 -> 82.95 | K42: 0.81 | L42: 0.91 | M42: =if(L42>1,L42/100,L42) -> 0.91 | N42: Company A | O42: =vlookup(N42,Interview_Slots!$A$1:$D$5,3,false) -> 65 | P42: =vlookup(N42,Interview_Slots!$A$1:$D$5,4,false) -> 75 | Q42: =IF(AND(J42>=O42,K42>=P42/100),"Eligible","Not Eligible") -> Eligible | R42: yes
...

Sheet Dept_Lookup
A1: Variant | B1: Standard_Department
A2: CSE | B2: Computer Science
A3: Comp Sci | B3: Computer Science
A4: CS | B4: Computer Science
A5: Computer Science | B5: Computer Science
A6: ECE | B6: Electronics
A7: Electro | B7: Electronics
A8: ELEC | B8: Electronics
A9: Electronics | B9: Electronics
A10: Mech | B10: Mechanical
A11: ME | B11: Mechanical
A12: Mechanical Engg | B12: Mechanical
... A17: Civil | B17: Civil

Sheet Interview_Slots
A1: Company | B1: Interview_Slots_Available | C1: Min_WeightedScore | D1: Min_Attendance_%
A2: Company A | B2: 60 | C2: 65 | D2: 75
A3: Company B | B3: 45 | C3: 70 | D3: 80
A4: Company C | B4: 80 | C4: 60 | D4: 70
A5: Company D | B5: 30 | C5: 75 | D5: 85

Sheet Scoring_Weights
A1: Test | B1: Weight
A2: Test_1 | B2: 0.15
A3: Test_2 | B3: 0.35
A4: Test_3 | B4: 0.5

Sheet Dashboard
I1: COUNTA of Name | J1: Allocation_Status
I2: Internship_Pref | J2: no | K2: yes | L2: Grand Total
I3: Company A | J3: 52 | K3: 60 | L3: 112
I4: Company B | J4: 27 | K4: 45 | L4: 72
I5: Company C | J5: 41 | K5: 80 | L5: 121
I6: Company D | J6: 17 | K6: 30 | L6: 47
I7: Grand Total | J7: 137 | K7: 215 | L7: 352
I44: COUNTA of Name | J44: Allocation_Status | R44: COUNTA of Name | S44: Eligibility
I45: Student_Department | J45: yes | K45: Grand Total | R45: Student_Department | S45: Eligible | T45: Not Eligible | U45: Grand Total
I46: Civil | J46: 52 | K46: 52 | R46: Civil | S46: 80 | T46: 36 | U46: 116
I47: Computer Science | J47: 53 | K47: 53 | R47: Computer Science | S47: 90 | T47: 35 | U47: 125
I48: Electronics | J48: 53 | K48: 53 | R48: Electronics | S48: 86 | T48: 43 | U48: 129
I49: Mechanical | J49: 57 | K49: 57 | R49: Mechanical | S49: 96 | T49: 44 | U49: 140
I50: Grand Total | J50: 215 | K50: 215 | R50: Grand Total | S50: 352 | T50: 158 | U50: 510
